Workbook

Sheet Sommaire
A1: Take-off civil – Développement rue Gaumont, Bâtiment A (Laval)
A2: Plans : C1 et C2 de 2, dossier 21002-A (CLA Experts-Conseils), révision du 2026-10-02 · Préparé le 2026-10-13 pour William Dubreuil, directeur construction, Les Entreprises PEP2000 inc.
A3: Préliminaire – à vérifier. Bâtiment B (présent dans le DWG seulement) exclu.
A5: Poste | B5: Quantité | C5: Unité | D5: Détail
A6: Conduite pluviale 900 TBA classe IV | B6: ='Pluvial – conduites'!F29 -> 352.4 | C6: m | D6: 4 tronçons RP-6 → RP-2
A7: Conduite pluviale 450 PVC DR35 | B7: ='Pluvial – conduites'!F30 -> 55.4 | C7: m | D7: RP-2 → RP-1
A8: Conduite pluviale 375 PVC DR35 | B8: ='Pluvial – conduites'!F31 -> 19.5 | C8: m | D8: RP-1 → séparateur → existant
A9: Conduite pluviale 300 PVC DR35 (latéraux, toit) | B9: ='Pluvial – conduites'!F32 -> 154.7 | C9: m
A10: Conduite pluviale 200 PVC DR35 | B10: ='Pluvial – conduites'!F33 -> 27.4 | C10: m | D10: P-11
A11: Drain PEHD perforé 200 (tranchée drainante) | B11: ='Pluvial – conduites'!F34 -> 330 | C11: m | D11: Estimé ; Wolseley en cote 370 m
A12: Regards pluviaux M-1600 (dont 1 avec régulateur) | B12: =6 -> 6 | C12: un. | D12: RP-1 à RP-6 (RP-3 à confirmer)
A13: Séparateur huile et sédiments | B13: =1 -> 1 | C13: un.
A14: Puisards Ø 1200 (bassins) | B14: =Structures!I29 -> 5 | C14: un.
A15: Puisards P-1 (P-600) | B15: =Structures!I30 -> 6 | C15: un.
A16: Regard sanitaire Ø 1200 | B16: =1 -> 1 | C16: un. | D16: RS-1
A17: Branchement sanitaire 150 PVC DR28 | B17: ='Sanitaire et aqueduc'!D5+'Sanitaire et aqueduc'!D6 -> 13.6 | C17: m
A18: Branchement aqueduc 200 PVC DR18 (gicleurs + domestique) | B18: ='Sanitaire et aqueduc'!D7 -> 11.7 | C18: m | D18: + raccordement sous pression et chambre VRE
A19: Excavation de tranchée (théorique, parois verticales) | B19: ='Pluvial – conduites'!M26 -> 1924.705 | C19: m³ | D19: Pluvial seulement
A20: Pierre d'assise et d'enrobage – pluvial | B20: ='Pluvial – conduites'!N26 -> 624.48521 | C20: m³
A21: Coupes de rue – pavage à refaire (rue Gaumont) | B21: ='Coupes de rue'!E9+'Coupes de rue'!F9 -> 212.5 | C21: m² | D21: 2 coupes + bandes aux entrées
A22: Bordure surbaissée à refaire dans l'emprise | B22: ='Coupes de rue'!G9 -> 57 | C22: m
A23: Pavage lourd type A | B23: =Surfaces!B7 -> 8506.165 | C23: m² | D23: Ajusté au total de l'ingénieur
A24: Pavage léger (stationnement) | B24: =Surfaces!B8 -> 2513.635 | C24: m²
A25: Enrobé total | B25: =Surfaces!B9+Surfaces!B10 -> 2433.6067 | C25: t
A26: Pierre MG-20 (fondation) | B26: =Surfaces!B11 -> 1652.97 | C26: m³
A27: Pierre MG-56 (fondation) | B27: =Surfaces!B12 -> 4581.8648 | C27: m³
A28: Bordure de béton (site) | B28: =Surfaces!B13 -> 1191 | C28: m
A29: Trottoirs de béton | B29: =Surfaces!B20 -> 238.4 | C29: m²
A30: Gazon en plaque | B30: =Surfaces!B22 -> 3777.2 | C30: m²
A31: Bassins de biorétention (aire d'infiltration) | B31: =Surfaces!B24 -> 1024.8 | C31: m² | D31: 5 bassins
A32: Isolant rigide HI-40 (croisements + faible couvert) | B32: =Surfaces!B30+Surfaces!B31 -> 702.45 | C32: m² | D32: À clarifier
A34: Voir l'onglet « Points à clarifier » : 6 points à impact élevé avant de fixer le prix.

Sheet Points à clarifier
A1: Points à clarifier et questions pour l'appel d'offres
A2: Classés par impact sur le prix.
A4: # | B4: Impact | C4: Sujet | D4: Constat | E4: Question / action proposée
A5: 1 | B5: Élevé | C5: Couvert de la 900Ø | D5: Entre RP-4 et RP-2, le couvert de la 900Ø (D – R – D ext.) n'est que de 0,43 à 0,69 m. C'est moins que l'épaisseur de la structure de chaussée lourde (700 mm) : la couronne empiète dans la fondation MG-56. | E5: Confirmer les radiers, la classe de TBA requise sous charge lourde et l'isolation (note 3.14 : pluvial < 1,2 m de couvert → isolant, ≈ 305 m de 900Ø). Le tableau d'isolant ne couvre pas un couvert < 600 mm.
A6: 2 | B6: Élevé | C6: Bâtiment B dans le DWG | D6: Le fichier DWG contient aussi un 2e réseau au nord de la rue Gaumont (pluvial 900Ø ≈ 520 m, puisards, sanitaire 150 ≈ 45 m, aqueduc 200 ≈ 65 m) qui n'apparaît pas sur le PDF C1. | E6: Confirmer que la soumission couvre uniquement le bâtiment A (exclus du présent take-off).
A7: 3 | B7: Élevé | C7: RP-3 indiqué M-900 | D7: Un regard M-900 ne peut pas recevoir des conduites de 900 mm. | E7: Confirmer M-1600 (comme RP-2, RP-4, RP-5).
A8: 4 | B8: Élevé | C8: Sanitaire – regard RS-1 | D8: Le radier de RS-1 (R20,70) est plus haut que la sortie du bâtiment (R20,20), avec une profondeur de seulement 0,80 m, puis une chute d'environ 3,5 m vers R17,19 sur environ 8 m. | E8: Confirmer les élévations et préciser s'il faut un regard de chute ou un branchement en pente forte.
A9: 5 | B9: Moyen | C9: Matériau 900Ø | D9: La note 2.2 exige du TBA classe IV pour le pluvial 900. Une option PEHD constitue une substitution. | E9: Obtenir l'approbation écrite de l'ingénieur avant de soumettre en PEHD (déformation, enrobage complet, volume de rétention).
A10: 6 | B10: Moyen | C10: Raccordement aqueduc sous pression | D10: Chambre VRE modifiée 1165 × 1800 × 1800 et raccordement sous pression sur un 400 Hyprescon. | E10: Confirmer si le raccordement est exécuté par la Ville de Laval ou par l'entrepreneur, ainsi que les frais (note 1.9).
A11: 7 | B11: Moyen | C11: Séparateur huile/sédiments | D11: Modèle non spécifié (40 % MES à 111,9 L/s). | E11: Demander le modèle de base et les équivalents acceptés.
A12: 8 | B12: Moyen | C12: Régulateur RP-1 | D12: Bouchon IPEX sur mesure, Q = 111,9 L/s à 1,563 m. | E12: Fourniture spéciale : obtenir le prix d'IPEX.
A13: 9 | B13: Moyen | C13: Tranchée drainante | D13: Longueur non cotée (≈ 330 m estimés). Les éléments « D20,75 R20,65 », « D20,60 R19,15 » et « D20,60 R19,65 » le long de la bordure ne sont pas détaillés (puits de nettoyage ?). | E13: Préciser la longueur, les raccords et les ouvrages.
A14: 10 | B14: Moyen | C14: Murets | D14: « Nouveau muret » et « muret ou talus » sans détail. | E14: Fournir le type, la hauteur et la longueur.
A15: 11 | B15: Faible | C15: P-7 | D15: D19,80 sous le fond du bassin centre-ouest (F20,20). | E15: Vérifier l'élévation (probablement 20,50).
A16: 12 | B16: Faible | C16: Conduites de toit | D16: Sorties 250Ø (R19,70), mais conduites étiquetées 300Ø (24,6 m et 24,8 m). | E16: Confirmer le diamètre et le réducteur.
... A27: 23 | B27: Info | C27: Statut des plans | D27: Note 1.1 : obtenir les plans « émis pour construction ». | E27: Confirmer la révision de soumission (C1/C2 datés du 2026-10-02).

Sheet Pluvial – conduites
A1: Égout pluvial – conduites
A2: Longueurs = étiquettes de l'ingénieur (C1) ; regards c/c. Profondeur = D – R moyen. Excavation théorique à parois verticales (pentes CNESST en sus).
A4: Tronçon | B4: De | C4: À | D4: Ø (mm) | E4: Matériau (note C2 2.2) | F4: Longueur (m) | G4: Pente | H4: Prof. amont D-R (m) | I4: Prof. aval D-R (m) | J4: Prof. moy. (m) | K4: D ext. (m) | L4: Larg. tranchée (m) | M4: Excavation (m³) | N4: Pierre assise+enrobage (m³) | O4: Source | P4: Remarque
A5: PL-1 | B5: RP-6 | C5: RP-5 | D5: 900 | E5: TBA classe IV | F5: 37.3 | G5: 0.0024 | H5: 2.1 | I5: 2.39 | J5: =AVERAGE(H5:I5) -> 2.245 | K5: =Paramètres!$B$9 -> 1.104 | L5: =K5+Paramètres!$B$7 -> 2.004 | M5: =L5*(J5+Paramètres!$B$6)*F5 -> 184.63052 | N5: =F5*(L5*Paramètres!$B$6+L5*K5/2-PI()*K5^2/8) -> 40.227307 | O5: PDF C1 (étiquette ingénieur) | P5: Conduite de rétention
A6: PL-2 | B6: RP-5 | C6: RP-4 | D6: 900 | E6: TBA classe IV | F6: 103.8 | G6: 0.0023 | H6: 2.39 | I6: 1.45 | J6: =AVERAGE(H6:I6) -> 1.92 | K6: =Paramètres!$B$9 -> 1.104 | L6: =K6+Paramètres!$B$7 -> 2.004 | M6: =L6*(J6+Paramètres!$B$6)*F6 -> 446.1926 | N6: =F6*(L6*Paramètres!$B$6+L6*K6/2-PI()*K6^2/8) -> 111.94623 | O6: PDF C1 (étiquette ingénieur) | P6: Conduite de rétention
A7: PL-3 | B7: RP-4 | C7: RP-3 | D7: 900 | E7: TBA classe IV | F7: 116.6 | G7: 0.0017 | H7: 1.45 | I7: 1.68 | J7: =AVERAGE(H7:I7) -> 1.565 | K7: =Paramètres!$B$9 -> 1.104 | L7: =K7+Paramètres!$B$7 -> 2.004 | M7: =L7*(J7+Paramètres!$B$6)*F7 -> 418.26286 | N7: =F7*(L7*Paramètres!$B$6+L7*K7/2-PI()*K7^2/8) -> 125.75078 | O7: PDF C1 (étiquette ingénieur) | P7: Couvert < 1,2 m – voir Points à clarifier
A8: PL-4 | B8: RP-3 | C8: RP-2 | D8: 900 | E8: TBA classe IV | F8: 94.7 | G8: 0.0019 | H8: 1.68 | I8: 1.43 | J8: =AVERAGE(H8:I8) -> 1.555 | K8: =Paramètres!$B$9 -> 1.104 | L8: =K8+Paramètres!$B$7 -> 2.004 | M8: =L8*(J8+Paramètres!$B$6)*F8 -> 337.80626 | N8: =F8*(L8*Paramètres!$B$6+L8*K8/2-PI()*K8^2/8) -> 102.13206 | O8: PDF C1 (étiquette ingénieur) | P8: Couvert ≈ 0,4–0,7 m – voir Points à clarifier
A9: PL-5 | B9: RP-2 | C9: RP-1 | D9: 450 | E9: PVC DR35 | F9: 55.4 | G9: 0.0022 | H9: 1.43 | I9: 1.7 | J9: =AVERAGE(H9:I9) -> 1.565 | K9: =Paramètres!$B$12 -> 0.475 | L9: =K9+Paramètres!$B$7 -> 1.375 | M9: =L9*(J9+Paramètres!$B$5)*F9 -> 134.44887 | N9: =F9*(L9*Paramètres!$B$5+L9*(K9+Paramètres!$B$8)-PI()*K9^2/4) -> 64.453442 | O9: PDF C1 (étiquette ingénieur) | P9: 450 mm : PVC DR35 selon note 2.2 (200 à 450 mm)
A10: PL-6 | B10: RP-1 | C10: Séparateur | D10: 375 | E10: PVC DR35 | F10: 6.2 | G10: 0.0081 | H10: 1.7 | I10: 1.58 | J10: =AVERAGE(H10:I10) -> 1.64 | K10: =Paramètres!$B$11 -> 0.315 | L10: =K10+Paramètres!$B$7 -> 1.215 | M10: =L10*(J10+Paramètres!$B$5)*F10 -> 13.86072 | N10: =F10*(L10*Paramètres!$B$5+L10*(K10+Paramètres!$B$8)-PI()*K10^2/4) -> 5.656222 | O10: PDF C1 (étiquette ingénieur) | P10: Sortie régulée 111,9 L/s
A11: PL-7 | B11: Séparateur | C11: Exist. 600 TBA | D11: 375 | E11: PVC DR35 | F11: 13.3 | G11: 0.042 | H11: 1.58 | I11: 2.3 | J11: =AVERAGE(H11:I11) -> 1.94 | K11: =Paramètres!$B$11 -> 0.315 | L11: =K11+Paramètres!$B$7 -> 1.215 | M11: =L11*(J11+Paramètres!$B$5)*F11 -> 34.58133 | N11: =F11*(L11*Paramètres!$B$5+L11*(K11+Paramètres!$B$8)-PI()*K11^2/4) -> 12.133508 | O11: PDF C1 (étiquette ingénieur) | P11: Raccordement sur pluvial 600 TBA existant R±18,11 – coupe de rue CR-2
A12: LT-1 | B12: P-11 | C12: Bassin ouest | D12: 200 | E12: PVC DR35 | F12: 27.4 | G12: 0.0146 | H12: 0.6 | I12: 0.9 | J12: =AVERAGE(H12:I12) -> 0.75 | K12: =0.22 -> 0.22 | L12: =K12+Paramètres!$B$7 -> 1.12 | M12: =L12*(J12+Paramètres!$B$5)*F12 -> 29.1536 | N12: =F12*(L12*Paramètres!$B$5+L12*(K12+Paramètres!$B$8)-PI()*K12^2/4) -> 21.053796 | O12: PDF C1 (étiquette ingénieur) | P12: Prof. estimées
A13: LT-2 | B13: P-10 | C13: RP-6 | D13: 300 | E13: PVC DR35 | F13: 13.2 | G13: 0.0129 | H13: 1.73 | I13: 2.1 | J13: =AVERAGE(H13:I13) -> 1.915 | K13: =Paramètres!$B$11 -> 0.315 | L13: =K13+Paramètres!$B$7 -> 1.215 | M13: =L13*(J13+Paramètres!$B$5)*F13 -> 33.92037 | N13: =F13*(L13*Paramètres!$B$5+L13*(K13+Paramètres!$B$8)-PI()*K13^2/4) -> 12.042279 | O13: PDF C1 (étiquette ingénieur)
A14: LT-3 | B14: P-9 | C14: 900 (PL-1) | D14: 300 | E14: PVC DR35 | F14: 25 | H14: 1.73 | I14: 2.1 | J14: =AVERAGE(H14:I14) -> 1.915 | K14: =Paramètres!$B$11 -> 0.315 | L14: =K14+Paramètres!$B$7 -> 1.215 | M14: =L14*(J14+Paramètres!$B$5)*F14 -> 64.243125 | N14: =F14*(L14*Paramètres!$B$5+L14*(K14+Paramètres!$B$8)-PI()*K14^2/4) -> 22.807347 | O14: PDF C1 (étiquette ingénieur) | P14: Raccord direct sur la 900 (té / selle) – confirmer
A15: LT-4 | B15: Sortie toit 250 (ouest) | C15: 900 (PL-2) | D15: 300 | E15: PVC DR35 | F15: 24.6 | H15: 1.2 | I15: 1.8 | J15: =AVERAGE(H15:I15) -> 1.5 | K15: =Paramètres!$B$11 -> 0.315 | L15: =K15+Paramètres!$B$7 -> 1.215 | M15: =L15*(J15+Paramètres!$B$5)*F15 -> 50.8113 | N15: =F15*(L15*Paramètres!$B$5+L15*(K15+Paramètres!$B$8)-PI()*K15^2/4) -> 22.442429 | O15: PDF C1 (étiquette ingénieur) | P15: Sortie bâtiment 250Ø R19,70 – étiquette 300Ø ; réducteur à prévoir
A16: LT-5 | B16: P-7 | C16: 900 (PL-2) | D16: 300 | E16: PVC DR35 | F16: 15.6 | H16: 0.73 | I16: 1.6 | J16: =AVERAGE(H16:I16) -> 1.165 | K16: =Paramètres!$B$11 -> 0.315 | L16: =K16+Paramètres!$B$7 -> 1.215 | M16: =L16*(J16+Paramètres!$B$5)*F16 -> 25.87221 | N16: =F16*(L16*Paramètres!$B$5+L16*(K16+Paramètres!$B$8)-PI()*K16^2/4) -> 14.231784 | O16: PDF C1 (étiquette ingénieur) | P16: Vérifier D19,80 de P-7
A17: LT-6 | B17: P-6 | C17: 900 (PL-3) | D17: 300 | E17: PVC DR35 | F17: 10.8 | H17: 1.02 | I17: 1.45 | J17: =AVERAGE(H17:I17) -> 1.235 | K17: =Paramètres!$B$11 -> 0.315 | L17: =K17+Paramètres!$B$7 -> 1.215 | M17: =L17*(J17+Paramètres!$B$5)*F17 -> 18.83007 | N17: =F17*(L17*Paramètres!$B$5+L17*(K17+Paramètres!$B$8)-PI()*K17^2/4) -> 9.8527738 | O17: PDF C1 (étiquette ingénieur)
A18: LT-7 | B18: P-5 | C18: 900 (PL-3) | D18: 300 | E18: PVC DR35 | F18: 14.6 | H18: 1.33 | I18: 1.6 | J18: =AVERAGE(H18:I18) -> 1.465 | K18: =Paramètres!$B$11 -> 0.315 | L18: =K18+Paramètres!$B$7 -> 1.215 | M18: =L18*(J18+Paramètres!$B$5)*F18 -> 29.535435 | N18: =F18*(L18*Paramètres!$B$5+L18*(K18+Paramètres!$B$8)-PI()*K18^2/4) -> 13.31949 | O18: PDF C1 (étiquette ingénieur)
A19: LT-8 | B19: Sortie toit 250 (est) | C19: RP-3 | D19: 300 | E19: PVC DR35 | F19: 24.8 | H19: 1.2 | I19: 1.68 | J19: =AVERAGE(H19:I19) -> 1.44 | K19: =Paramètres!$B$11 -> 0.315 | L19: =K19+Paramètres!$B$7 -> 1.215 | M19: =L19*(J19+Paramètres!$B$5)*F19 -> 49.41648 | N19: =F19*(L19*Paramètres!$B$5+L19*(K19+Paramètres!$B$8)-PI()*K19^2/4) -> 22.624888 | O19: PDF C1 (étiquette ingénieur) | P19: Sortie bâtiment 250Ø R19,70 – étiquette 300Ø
A20: LT-9 | B20: P-04 | C20: RP-3 | D20: 300 | E20: PVC DR35 | F20: 10.5 | H20: 1.43 | I20: 1.68 | J20: =AVERAGE(H20:I20) -> 1.555 | K20: =Paramètres!$B$11 -> 0.315 | L20: =K20+Paramètres!$B$7 -> 1.215 | M20: =L20*(J20+Paramètres!$B$5)*F20 -> 22.389412 | N20: =F20*(L20*Paramètres!$B$5+L20*(K20+Paramètres!$B$8)-PI()*K20^2/4) -> 9.5790856 | O20: PDF C1 (étiquette ingénieur)
A21: LT-10 | B21: P-3 | C21: RP-2 | D21: 300 | E21: PVC DR35 | F21: 6.3 | H21: 1.33 | I21: 1.43 | J21: =AVERAGE(H21:I21) -> 1.38 | K21: =Paramètres!$B$11 -> 0.315 | L21: =K21+Paramètres!$B$7 -> 1.215 | M21: =L21*(J21+Paramètres!$B$5)*F21 -> 12.09411 | N21: =F21*(L21*Paramètres!$B$5+L21*(K21+Paramètres!$B$8)-PI()*K21^2/4) -> 5.7474514 | O21: PDF C1 (étiquette ingénieur)
A22: LT-11 | B22: P-1 | C22: PL-5 (450) | D22: 300 | E22: PVC DR35 | F22: 5.3 | H22: 1.43 | I22: 1.5 | J22: =AVERAGE(H22:I22) -> 1.465 | K22: =Paramètres!$B$11 -> 0.315 | L22: =K22+Paramètres!$B$7 -> 1.215 | M22: =L22*(J22+Paramètres!$B$5)*F22 -> 10.721768 | N22: =F22*(L22*Paramètres!$B$5+L22*(K22+Paramètres!$B$8)-PI()*K22^2/4) -> 4.8351575 | O22: PDF C1 (étiquette ingénieur)
A23: LT-12 | B23: P-2 | C23: PL-5 (450) | D23: 300 | E23: PVC DR35 | F23: 2 | H23: 1.4 | I23: 1.43 | J23: =AVERAGE(H23:I23) -> 1.415 | K23: =Paramètres!$B$11 -> 0.315 | L23: =K23+Paramètres!$B$7 -> 1.215 | M23: =L23*(J23+Paramètres!$B$5)*F23 -> 3.92445 | N23: =F23*(L23*Paramètres!$B$5+L23*(K23+Paramètres!$B$8)-PI()*K23^2/4) -> 1.8245877 | O23: Estimé – à valider | P23: Puisard sur la ligne – raccord court estimé
A24: LT-13 | B24: P-8 | C24: PL-2 (900) | D24: 300 | E24: PVC DR35 | F24: 2 | H24: 1.4 | I24: 1.5 | J24: =AVERAGE(H24:I24) -> 1.45 | K24: =Paramètres!$B$11 -> 0.315 | L24: =K24+Paramètres!$B$7 -> 1.215 | M24: =L24*(J24+Paramètres!$B$5)*F24 -> 4.0095 | N24: =F24*(L24*Paramètres!$B$5+L24*(K24+Paramètres!$B$8)-PI()*K24^2/4) -> 1.8245877 | O24: Estimé – à valider | P24: Puisard sur la ligne – raccord court estimé
A25: DR-1 | B25: Tranchée drainante | C25: Réseau | D25: 200 | E25: Drain PEHD perforé 200Ø | F25: 330 | H25: 0.6 | I25: 0.6 | J25: =AVERAGE(H25:I25) -> 0.6 | K25: =0.22 -> 0.22 | L25: =1 -> 1 | M25: =0 -> 0 | N25: =0 -> 0 | O25: Estimé – à valider | P25: Le long de la bordure sud (RP-5 → RP-2) ; longueur non cotée – voir Surfaces
A26: TOTAL | F26: =SUM(F5:F25) -> 939.4 | M26: =SUM(M5:M25) -> 1924.705 | N26: =SUM(N5:N25) -> 624.48521
A28: Sous-totaux par diamètre / matériau
A29: 900 TBA classe IV | F29: =SUMIFS(F5:F25,D5:D25,900,A5:A25,"<>DR*") -> 352.4 | G29: m
A30: 450 PVC DR35 | F30: =SUMIFS(F5:F25,D5:D25,450,A5:A25,"<>DR*") -> 55.4 | G30: m
A31: 375 PVC DR35 | F31: =SUMIFS(F5:F25,D5:D25,375,A5:A25,"<>DR*") -> 19.5 | G31: m
A32: 300 PVC DR35 | F32: =SUMIFS(F5:F25,D5:D25,300,A5:A25,"<>DR*") -> 154.7 | G32: m
A33: 200 PVC DR35 | F33: =SUMIFS(F5:F25,D5:D25,200,A5:A25,"<>DR*") -> 27.4 | G33: m
A34: Drain PEHD perforé 200 (tranchée drainante) | F34: =SUMIFS(F5:F25,A5:A25,"DR*") -> 330 | G34: m

Sheet Structures
A1: Regards, puisards et ouvrages
A2: D = dessus (couvercle/grille), R = radier, Re/Rs = radier entrée/sortie, F = fond. Profondeur = D – R (ou D – F pour les puisards).
A4: No | B4: Type | C4: Modèle / diamètre | D4: D (m) | E4: R / Rs (m) | F4: Re (m) | G4: F (m) | H4: Profondeur (m) | I4: Qté | J4: Source | K4: Remarque
A5: RP-1 | B5: Regard pluvial avec régulateur | C5: M-1600 + régulateur type bouchon IPEX sur mesure | D5: 20.5 | E5: 18.8 | G5: 18.35 | H5: =IF(D5="","",IF(G5<>"",D5-G5,D5-E5)) -> 2.15 | I5: 1 | J5: PDF C1 (étiquette ingénieur) | K5: Q = 111,9 L/s à 1,563 m ; sortie 375Ø
A6: RP-2 | B6: Regard pluvial | C6: M-1600 | D6: 20.35 | E6: 18.92 | H6: =IF(D6="","",IF(G6<>"",D6-G6,D6-E6)) -> 1.43 | I6: 1 | J6: PDF C1 (étiquette ingénieur) | K6: Couvert 900Ø ≈ 0,43 m
A7: RP-3 | B7: Regard pluvial | C7: M-900 (indiqué) | D7: 20.78 | E7: 19.1 | H7: =IF(D7="","",IF(G7<>"",D7-G7,D7-E7)) -> 1.68 | I7: 1 | J7: PDF C1 (étiquette ingénieur) | K7: ⚠ M-900 incompatible avec 900Ø – probablement M-1600
A8: RP-4 | B8: Regard pluvial | C8: M-1600 | D8: 20.75 | E8: 19.3 | H8: =IF(D8="","",IF(G8<>"",D8-G8,D8-E8)) -> 1.45 | I8: 1 | J8: PDF C1 (étiquette ingénieur)
A9: RP-5 | B9: Regard pluvial | C9: M-1600 | D9: 21.93 | E9: 19.54 | H9: =IF(D9="","",IF(G9<>"",D9-G9,D9-E9)) -> 2.39 | I9: 1 | J9: PDF C1 (étiquette ingénieur)
A10: RP-6 | B10: Regard pluvial | C10: M-1600 | D10: 21.73 | E10: 19.63 | F10: 20.5 | H10: =IF(D10="","",IF(G10<>"",D10-G10,D10-E10)) -> 2.1 | I10: 1 | J10: PDF C1 (étiquette ingénieur) | K10: Rs 19,63 / Re 20,50
A11: SEP-1 | B11: Séparateur huile et sédiments | C11: À préciser (40 % MES à 111,9 L/s) | D11: 20.33 | E11: 18.75 | H11: =IF(D11="","",IF(G11<>"",D11-G11,D11-E11)) -> 1.58 | I11: 1 | J11: PDF C1 (étiquette ingénieur) | K11: Modèle non spécifié
A12: P-1 | B12: Puisard avec grille bombée (bassin est) | C12: Ø 1200 avec raccord drains (détail C2) | D12: 20.4 | E12: 19.43 | F12: 18.975 | G12: 18.67 | H12: =IF(D12="","",IF(G12<>"",D12-G12,D12-E12)) -> 1.73 | I12: 1 | J12: PDF C1 (étiquette ingénieur)
A13: P-2 | B13: Puisard | C13: P-1 (P-600) avec cloche, réserve 300 | D13: 20.55 | E13: 19.15 | G13: 18.85 | H13: =IF(D13="","",IF(G13<>"",D13-G13,D13-E13)) -> 1.7 | I13: 1 | J13: PDF C1 (étiquette ingénieur)
A14: P-3 | B14: Puisard | C14: P-1 (P-600) avec cloche, réserve 300 | D14: 20.63 | E14: 19.3 | G14: 19 | H14: =IF(D14="","",IF(G14<>"",D14-G14,D14-E14)) -> 1.63 | I14: 1 | J14: PDF C1 (étiquette ingénieur)
A15: P-04 | B15: Puisard (bassin centre-est) | C15: Ø 1200 avec raccord drains (détail C2) | D15: 20.25 | E15: 19.28 | F15: 18.825 | G15: 18.52 | H15: =IF(D15="","",IF(G15<>"",D15-G15,D15-E15)) -> 1.73 | I15: 1 | J15: PDF C1 (étiquette ingénieur)
A16: P-5 | B16: Puisard | C16: P-1 (P-600) avec cloche, réserve 300 | D16: 20.63 | E16: 19.3 | G16: 19 | H16: =IF(D16="","",IF(G16<>"",D16-G16,D16-E16)) -> 1.63 | I16: 1 | J16: PDF C1 (étiquette ingénieur)
A17: P-6 | B17: Puisard | C17: P-1 (P-600) avec cloche, réserve 300 | D17: 20.62 | E17: 19.6 | G17: 19.1 | H17: =IF(D17="","",IF(G17<>"",D17-G17,D17-E17)) -> 1.52 | I17: 1 | J17: PDF C1 (étiquette ingénieur)
A18: P-7 | B18: Puisard (bassin centre-ouest) | C18: Ø 1200 avec raccord drains (détail C2) | D18: 19.8 | E18: 19.53 | F18: 19.075 | G18: 18.27 | H18: =IF(D18="","",IF(G18<>"",D18-G18,D18-E18)) -> 1.53 | I18: 1 | J18: PDF C1 (étiquette ingénieur) | K18: ⚠ D19,80 sous le fond du bassin (F20,20) – à vérifier
A19: P-8 | B19: Puisard | C19: P-1 (P-600) avec cloche, réserve 300 | D19: 21.75 | E19: 20.35 | G19: 20.05 | H19: =IF(D19="","",IF(G19<>"",D19-G19,D19-E19)) -> 1.7 | I19: 1 | J19: PDF C1 (étiquette ingénieur)
A20: P-9 | B20: Puisard avec grille bombée (bassin ouest-bas) | C20: Ø 1200 avec raccord drains (détail C2) | D20: 21.6 | E20: 20.33 | F20: 19.875 | G20: 19.58 | H20: =IF(D20="","",IF(G20<>"",D20-G20,D20-E20)) -> 2.02 | I20: 1 | J20: PDF C1 (étiquette ingénieur)
A21: P-10 | B21: Puisard avec grille bombée (bassin ouest) | C21: Ø 1200 avec raccord drains (détail C2) | D21: 21.6 | E21: 20.33 | F21: 19.875 | G21: 19.58 | H21: =IF(D21="","",IF(G21<>"",D21-G21,D21-E21)) -> 2.02 | I21: 1 | J21: PDF C1 (étiquette ingénieur)
A22: P-11 | B22: Puisard | C22: P-1 (P-600) avec cloche, réserve 300 | D22: 22 | E22: 21.4 | G22: 20.9 | H22: =IF(D22="","",IF(G22<>"",D22-G22,D22-E22)) -> 1.1 | I22: 1 | J22: PDF C1 (étiquette ingénieur)
A23: RS-1 | B23: Regard sanitaire | C23: Ø 1200 avec cunette demi-diamètre | D23: 21.5 | E23: 20.7 | H23: =IF(D23="","",IF(G23<>"",D23-G23,D23-E23)) -> 0.8 | I23: 1 | J23: PDF C1 (étiquette ingénieur) | K23: ⚠ Radier plus haut que la sortie du bâtiment (R20,20)
A24: CV-1 | B24: Chambre de vanne – aqueduc | C24: VRE modifiée 1165 × 1800 × 1800 mm | H24: =IF(D24="","",IF(G24<>"",D24-G24,D24-E24)) | I24: 1 | J24: PDF C1 (étiquette ingénieur) | K24: Raccordement sous pression sur 400Ø Hyprescon existant
A25: TOTAL | I25: =SUM(I5:I24) -> 20
A27: Comptes
A28: Regards pluviaux M-1600 (incl. RP-1 et RP-3 si corrigé) | I28: =COUNTIF(C5:C24,"M-1600*")+COUNTIF(C5:C24,"M-900*") -> 6
A29: Puisards Ø 1200 (bassins de biorétention) | I29: =COUNTIF(C5:C24,"Ø 1200 avec raccord*") -> 5
A30: Puisards P-1 (P-600) | I30: =COUNTIF(C5:C24,"P-1 (P-600)*") -> 6

Sheet Sanitaire et aqueduc
A1: Branchements sanitaire et aqueduc
A2: Services amenés à 0,9 m du bâtiment (note C2 3.10). Longueurs mesurées dans le DWG à l'échelle.
A4: Élément | B4: Ø (mm) | C4: Matériau | D4: Longueur (m) | E4: Raccordement | F4: Source | G4: Remarque
A5: Sanitaire : bâtiment → RS-1 | B5: 150 | C5: PVC DR28 noir | D5: 5.5 | E5: Sortie bâtiment R20,20 | F5: DWG (mesuré) | G5: Longueur jusqu'à 0,9 m du bâtiment
A6: Sanitaire : RS-1 → égout existant | B6: 150 | C6: PVC DR28 noir | D6: 8.1 | E6: Sur SAN 300 PVC existant (R±17,04), nouveau radier R17,19 – percement / selle | F6: DWG (mesuré) | G6: Chute ≈ 3,5 m : regard de chute ? – voir Points à clarifier
A7: Aqueduc gicleurs + domestique | B7: 200 | C7: PVC DR18 | D7: 11.7 | E7: Sous pression sur AQ 400 Hyprescon existant – chambre VRE modifiée | F7: DWG (mesuré) | G7: Siamoises sur le bâtiment (plomberie). Isolant si couvert < 2,0 m
A8: TOTAL | D8: =SUM(D5:D7) -> 25.3

Sheet Coupes de rue
A1: Coupes de rue et travaux dans l'emprise (rue Gaumont)
A2: Mesuré dans le DWG (hachures « pavage » et « démolition »). Trait de scie à la jonction existant/neuf + transition à 45° (note C2 3.11).
A4: No | B4: Description | C4: Longueur (m) | D4: Largeur (m) | E4: Pavage (m²) | F4: Piste cyclable (m²) | G4: Bordure à refaire (m) | H4: Trait de scie (m) | I4: Réseaux touchés | J4: Remarque
A5: CR-1 | B5: Branchements sanitaire 150 + aqueduc 200 (centre, devant salle des gicleurs) | C5: 13.9 | D5: 8.5 | E5: =C5*D5 -> 118.15 | F5: 18.7 | G5: 8.5 | H5: =2*C5+D5+2*2.2 -> 40.7 | I5: SAN 300 PVC, AQ 400 Hyprescon (raccord sous pression), croisement PLUV 600 TBA et gaz 114 mm | J5: Coordination Ville (note 3.1) ; frais/dépôts municipaux (note 1.9)
A6: CR-2 | B6: Raccordement pluvial 375 → PLUV 600 TBA existant (entrée est) | C6: 10.3 | D6: 5 | E6: =C6*D6 -> 51.5 | F6: 0 | G6: 0 | H6: =2*C6+D6 -> 25.6 | I6: PLUV 600 TBA (R±18,11), croise AQ 400 Hyprescon et gaz | J6: Coupe dans l'entrée charretière
A7: ENT-O | B7: Entrée ouest – bordure surbaissée à refaire + bande de pavage | C7: 23.1 | D7: 0.5 | E7: =C7*D7 -> 11.55 | F7: 0 | G7: 23.2 | H7: =C7 -> 23.1 | I7: — | J7: Démolition bordure existante 23,2 m
A8: ENT-E | B8: Entrée est – bordure surbaissée à refaire + bande de pavage | C8: 25.2 | D8: 0.5 | E8: =C8*D8 -> 12.6 | F8: 0 | G8: 25.3 | H8: =C8 -> 25.2 | I8: — | J8: Démolition bordure existante 25,3 m
A9: TOTAL | E9: =SUM(E5:E8) -> 193.8 | F9: =SUM(F5:F8) -> 18.7 | G9: =SUM(G5:G8) -> 57 | H9: =SUM(H5:H8) -> 114.6
A11: Note : la structure de chaussée de la remise en état dans la rue doit suivre les exigences de la Ville de Laval (non précisées au plan).

Sheet Surfaces
A1: Voirie et aménagement de surface
A2: Pavage : surfaces mesurées sur le PDF (teintes foncée / pâle), ajustées au total de l'ingénieur. Bordures, trottoirs et gazon : implantation intégrée au DWG.
A4: Élément | B4: Quantité | C4: Unité | D4: Structure / détail (C2) | E4: Source | F4: Remarque
A5: Pavage lourd type A – surface mesurée | B5: 8122.3 | C5: m² | D5: EB-14 60 mm + EB-10S 40 mm / MG-20 150 / MG-56 450 | E5: PDF (mesuré) | F5: Inclut entrées et coupe CR-1
A6: Pavage léger (stationnement) – surface mesurée | B6: 2400.2 | C6: m² | D6: EB-10S 65 mm / MG-20 150 / MG-56 300 | E6: PDF (mesuré) | F6: Stationnements nord-ouest et nord-est
A7: Pavage lourd – ajusté au total ingénieur | B7: =B5*Paramètres!$B$23 -> 8506.165 | C7: m² | E7: Estimé – à valider | F7: Total ingénieur pavage = 11 019,8 m²
A8: Pavage léger – ajusté au total ingénieur | B8: =B6*Paramètres!$B$23 -> 2513.635 | C8: m² | E8: Estimé – à valider
A9: Enrobé EB-14 (lourd) | B9: =B7*0.06*Paramètres!$B$14 -> 1224.8878 | C9: t | D9: 60 mm | E9: Calcul
A10: Enrobé EB-10S (lourd 40 mm + léger 65 mm) | B10: =(B7*0.04+B8*0.065)*Paramètres!$B$14 -> 1208.7189 | C10: t | E10: Calcul
A11: Pierre MG-20 – fondation supérieure 150 mm | B11: =(B7+B8)*0.15 -> 1652.97 | C11: m³ | D11: Comp. 95 % P.M. | E11: Calcul
A12: Pierre MG-56 – fondation inférieure | B12: =B7*0.45+B8*0.3 -> 4581.8648 | C12: m³ | D12: 450 mm (lourd) / 300 mm (léger) | E12: Calcul
A13: Bordure de béton – total site | B13: 1191 | C13: m | D13: Bordure 32 MPa, 200 × 400 (détail C2) | E13: DWG (implantation) | F13: Total des composantes ci-dessous ; ± 5 % (version polygonale vs courbes du civil)
A14: dont bordure périphérique (entrée est → sud → entrée ouest) | B14: 502.6 | C14: m | E14: DWG (implantation)
A15: dont îlots / bordures intérieures ouest + est | B15: 238 | C15: m | E15: DWG (implantation) | F15: 125,0 + 112,9
A16: dont bordures des stationnements nord | B16: 173.5 | C16: m | E16: DWG (implantation)
A17: dont bordures le long des quais / façade sud | B17: 227.7 | C17: m | E17: DWG (implantation)
A18: dont divers (bouts, retours) | B18: 49.2 | C18: m | E18: DWG (implantation)
A19: Bordure de béton surbaissée (entrées sur rue Gaumont) | B19: 48.5 | C19: m | D19: Détail bordure surbaissée C2 | E19: DWG | F19: Voir Coupes de rue
A20: Trottoir de béton (mesuré) | B20: 238.4 | C20: m² | D20: 150 mm béton 32 MPa / fondation pierre nette 20 mm 150 mm | E20: DWG (implantation) | F20: Tableau ingénieur = 160,8 m² – à clarifier
A21: dont paliers de portes | B21: 17 | C21: m² | D21: 10 paliers × 1,7 m² | E21: DWG
A22: Gazon en plaque sur 150 mm de terre végétale | B22: 3777.2 | C22: m² | D22: BNQ 0605-100 | E22: DWG (implantation) | F22: Tableau ingénieur « végétation » = 3 991,4 m²
A23: Terre végétale 150 mm | B23: =B22*0.15 -> 566.58 | C23: m³ | E23: Calcul
A24: Bassins de biorétention (5) – aire d'infiltration | B24: 1024.8 | C24: m² | D24: Ouest 312,0 / ouest-bas 123,0 / centre-ouest 246,0 / centre-est 162,6 / est 181,2 | E24: PDF C1 | F24: Volumes ci-dessous selon coupe C2 – épaisseurs à confirmer
A25: Substrat CSA W200-18 (≈ 500 mm) | B25: =B24*0.5 -> 512.4 | C25: m³ | E25: Estimé – à valider
A26: Filtre granulaire 3-10 mm (100 mm) | B26: =B24*0.1 -> 102.48 | C26: m³ | E26: Estimé – à valider
A27: Pierre nette 50 mm (≈ 450 mm) | B27: =B24*0.45 -> 461.16 | C27: m³ | E27: Estimé – à valider
A28: Tranchée drainante (1000 × 600, pierre nette 20 mm + drain PEHD perf. 200) | B28: 330 | C28: m | D28: Coupe tranchée drainante C2 | E28: Estimé – à valider | F28: Longueur non cotée
A29: Pierre nette 20 mm | B29: =B28*(1*0.6-PI()*0.11^2) -> 185.45562 | C29: m³ | E29: Calcul
A30: Isolant rigide HI-40 50 mm – croisements montrés (3) | B30: 36 | C30: m² | D30: 3 × ≈ 1,9 m × 6 m | E30: Estimé – à valider | F30: Dimensions non cotées
A31: Isolant rigide HI-40 – conduites à faible couvert (note 3.14) | B31: =305*Paramètres!$B$17+55*Paramètres!$B$18 -> 666.45 | C31: m² | D31: ≈ 305 m de 900Ø + 55 m de 450Ø à < 1,2 m de couvert | E31: Estimé – à valider | F31: Non montré au plan mais exigé « montré ou non » – voir Points à clarifier
A32: Nouveaux murets / muret ou talus | B32: 130 | C32: m | D32: Aucun détail fourni | E32: Estimé – à valider | F32: À clarifier (type, hauteur)
A33: Marquage de stationnement | B33: 1 | C33: global | D33: Lignes jaunes 100 mm, symboles PMR | E33: PDF C1 | F33: Voir plan d'architecte (note 3.15)

Sheet Démolition
A1: Démolition et préparation
A2: Mesuré dans le DWG (calques « démolition »).
A4: Élément | B4: Quantité | C4: Unité | D4: Source | E4: Remarque
A5: Bordure de béton existante à démolir (entrées) | B5: 48.5 | C5: m | D5: DWG (mesuré) | E5: Ouest 23,2 + est 25,3
A6: Bordure existante à démolir – coupe CR-1 | B6: 8.5 | C6: m | D6: DWG (mesuré)
A7: Pavage existant à démolir (rue Gaumont) | B7: =SUM('Coupes de rue'!E5:F8) -> 212.5 | C7: m² | D7: Calcul | E7: Coupes CR-1, CR-2 et bandes aux entrées
A8: Fossé existant à remblayer (côté est) | B8: 41.3 | C8: m | D8: DWG (mesuré) | E8: « Fossé à remblayer »
A9: Coupe / protection des arbres | B9: 1 | C9: global | D9: C2 note 3.9 | E9: Selon rapport du biologiste (non fourni)

Sheet TBA vs PEHD
A1: Comparatif TBA (Lécuyer) vs PEHD optimisé (Wolseley / Soleno) – réseau pluvial
A2: Prix matériel avant taxes. Bleu = prix des soumissions reçues ; jaune = à saisir ou à confirmer ; « Estimé » = valeur de Claude à remplacer par un prix réel.
A4: Poste | B4: Option A – TBA | C4: Option B – PEHD | D4: Source | E4: Note
A5: TBA 900 classe IV – 352,5 m × 380,20 $ | B5: 134020.5 | D5: Lécuyer 44746-TBAPX-R1 | E5: Joints caoutchouc inclus ; 141 tuyaux de 2,5 m
A6: Transport TBA (11 voyages théoriques) | B6: 12364 | D6: Lécuyer 44746-TBAPX-R1
A7: Regards RP-1 à RP-6 (béton) | B7: 29778.8 | D7: Lécuyer 44746-EGPX-R2 | E7: Fonte exclue ; RP-1 coté M-1200 (plan : M-1600)
A8: Ajustement RP-1 en M-1600 (au lieu de M-1200) | B8: 2966 | D8: Estimé | E8: Moyenne des M-1600 Lécuyer (5 457 $) moins 2 491,60 $ ; à confirmer
A9: Puisards P-1 à P-11 (béton, 11 un.) | B9: 13021.6 | D9: Lécuyer 44746-EGPX-R2 | E9: Fonte exclue
A10: Séparateur StormSettler STL-7 + transport | B10: 44263.33 | D10: Lécuyer 44746-UTPX-R1 | E10: 43 139,33 + 1 124,00
A11: Transport des regards et puisards (≈ 49 t, 2 voyages) | B11: 2248 | D11: Estimé (grille Lécuyer)
A12: Fonte des regards et puisards (17 un.) | B12: 15163 | D12: Estimé (prix unitaires Wolseley) | E12: 6 regards × 993 + 5 grilles dôme × 683 + 6 puisards × 965
A13: Latéraux PVC DR35 : 300 (112 m), 375 (20 m), 450 (56 m) + 2 tés 450×300 | B13: 18580.84 | D13: Wolseley QP062953 (lignes ALT) | E13: Produits alternatifs non inclus au total Wolseley
A14: Raccords des latéraux sur la 900 TBA (carottage + Kor-N-Seal, 6 un.) | B14: 3300 | D14: Estimé | E14: Té monolithique non compris chez Lécuyer
A15: Escompte Lécuyer sur le tuyau TBA | B15: =-B5*Paramètres!$B$19 -> -40206.15 | D15: Escompte (Paramètres) | E15: % modifiable dans Paramètres
A16: Escompte Lécuyer sur les regards (RP-1 à RP-6, incl. ajustement RP-1) | B16: =-(B7+B8)*Paramètres!$B$20 -> -9823.44 | D16: Escompte (Paramètres)
A17: Escompte Lécuyer sur l'unité de traitement (hors transport) | B17: =-(B10-1124)*Paramètres!$B$21 -> -6470.8995 | D17: Escompte (Paramètres) | E17: Transport net, non escompté
A18: Escompte Lécuyer sur les puisards (variante) | B18: =-B9*Paramètres!$B$22 -> 0 | D18: Escompte (Paramètres) | E18: 0 % par défaut
A19: Régulateur de débit type bouchon 375 | B19: 1565.86 | C19: 1565.86 | D19: Wolseley QP062953 | E19: Même produit dans les deux options
A20: Réseau SFM 900 Soleno (378 m, 5 cheminées-regards RP-2 à RP-6, coudes, raccords des puisards) | C20: 112631.55 | D20: Wolseley QP062953 option 2 | E20: Croquis Soleno PRO085820
A21: Latéraux PEHD CGI : 450 (60 m), 375 (30 m), 300 (102 m) | C21: 9678.84 | D21: Wolseley QP062953 option 2 | E21: 4 218,00 + 1 649,10 + 3 811,74
A22: Unité de traitement CDS-8 (béton) | C22: 50300 | D22: Wolseley QP062953 option 2 | E22: Mains de levage non fournies
A23: Adaptateurs de regard 375 (CDS) | C23: 327.46 | D23: Wolseley QP062953 option 2
A24: RP-1 regard PEHD lisse 900 H 2,15 m + fonte | C24: 3272.08 | D24: Wolseley QP062953 option 2 | E24: 2 279,03 + 234,00 + 386,72 + 372,33
A25: Puisards PEHD 600 (10 un.) + cadres et grilles | C25: 14067.3 | D25: Wolseley QP062953 option 2 | E25: Un 11e puisard manque (ligne suivante)
A26: 11e puisard (P-11), manquant chez Wolseley | C26: 1723 | D26: Estimé | E26: 758,32 + fonte 965
A27: Fonte des 5 cheminées-regards RP-2 à RP-6 | C27: 4965 | D27: Estimé (prix unitaires Wolseley) | E27: Non listée dans la soumission Wolseley
A28: Transport Soleno (7 voyages) | C28: 4025 | D28: Wolseley QP062953 option 2
A29: SOUS-TOTAL MATÉRIEL | B29: =SUM(B5:B28) -> 220771.44 | C29: =SUM(C5:C28) -> 202556.09
A31: Installation – différences entre les options
A32: Pierre MG-20B d'assise et d'enrobage par m de 900 (m³/m) | B32: =(Paramètres!$B$9+Paramètres!$B$7)*Paramètres!$B$6+(Paramètres!$B$9+Paramètres!$B$7)*Paramètres!$B$9/2-PI()*Paramètres!$B$9^2/8 -> 1.0784801 | C32: =(Paramètres!$B$10+Paramètres!$B$7)*Paramètres!$B$6+(Paramètres!$B$10+Paramètres!$B$7)*(Paramètres!$B$10+Paramètres!$B$8)-PI()*Paramètres!$B$10^2/4 -> 2.2091007 | D32: Calcul (C2 note E) | E32: TBA : enrobage jusqu'à mi-conduite ; PEHD : 300 mm au-dessus
A33: Pierre MG-20B totale (t) | B33: =B32*SUMIFS('Pluvial – conduites'!F5:F25,'Pluvial – conduites'!D5:D25,900)*Paramètres!$B$13 -> 836.12403 | C33: =C32*SUMIFS('Pluvial – conduites'!F5:F25,'Pluvial – conduites'!D5:D25,900)*Paramètres!$B$13 -> 1712.6716 | D33: Calcul
A34: Prix de la pierre MG-20B livrée ($/t) | D34: À SAISIR | E34: Même prix pour les deux options (cellule B)
A35: Coût de la pierre | B35: =IF($B$34="","",B33*$B$34) | C35: =IF($B$34="","",C33*$B$34) | D35: Calcul
A36: Production de pose de la 900 (m/jour) | D36: À SAISIR | E36: Vos équipes
A37: Coût équipe + équipement ($/jour) | D37: À SAISIR | E37: Option B : équipement plus léger possible
A38: Coût de pose de la 900 | B38: =IF(OR(B36="",B37=""),"",SUMIFS('Pluvial – conduites'!F5:F25,'Pluvial – conduites'!D5:D25,900)/B36*B37) | C38: =IF(OR(C36="",C37=""),"",SUMIFS('Pluvial – conduites'!F5:F25,'Pluvial – conduites'!D5:D25,900)/C36*C37) | D38: Calcul
A39: COÛT COMPARABLE (matériel + pierre + pose) | B39: =B29+N(B35)+N(B38) -> 220771.44 | C39: =C29+N(C35)+N(C38) -> 202556.09
A40: Écart B – A (négatif = PEHD moins cher) | C40: =C39-B39 -> -18215.351
A41: Seuil : prix de la pierre ($/t) qui annule l'économie sur le matériel | C41: =(B29-C29)/(C33-B33) -> 20.78079
A43: Éléments communs aux deux options, exclus du comparatif : drain perforé 200 (370 m), PVC 200/250 DR35, sanitaire 150, aqueduc, RS-1.
...

Sheet Paramètres
A1: Paramètres de calcul
A2: Toutes les constantes utilisées par les formules. Cellules en bleu = valeurs modifiables. Sources : feuille C2 (coupes et détails) sauf mention.
A4: Paramètre | B4: Valeur | C4: Unité | D4: Source / note
A5: Assise – conduite ≤ 600 mm | B5: 0.2 | C5: m | D5: C2 Tableau 1 (dans le sol)
A6: Assise – conduite 675 à 1200 mm | B6: 0.225 | C6: m | D6: C2 Tableau 1 (dans le sol)
A7: Surlargeur de tranchée (D ext. + …) | B7: 0.9 | C7: m | D7: C2 Tableau 1 – tranchée non étançonnée
A8: Enrobage au-dessus de la couronne (conduite flexible) | B8: 0.3 | C8: m | D8: C2 Section type tranchée commune
A9: Diamètre ext. TBA 900 classe IV | B9: 1.104 | C9: m | D9: Hypothèse : paroi B ≈ 102 mm (ASTM C76) – confirmer avec fournisseur
A10: Diamètre ext. PEHD 900 double paroi | B10: 1.052 | C10: m | D10: Hypothèse : ext. ≈ 1 052 mm (type N-12) – confirmer avec fournisseur
A11: Diamètre ext. PVC 300 | B11: 0.315 | C11: m | D11: Nominal
A12: Diamètre ext. PVC 450 | B12: 0.475 | C12: m | D12: Nominal
A13: Densité en place pierre MG-20 / MG-20B | B13: 2.2 | C13: t/m³ | D13: Hypothèse usuelle
A14: Densité enrobé bitumineux | B14: 2.4 | C14: t/m³ | D14: Hypothèse usuelle
A15: Facteur de foisonnement déblais | B15: 1.25 | C15: - | D15: Hypothèse usuelle (transport)
A16: Couvert min. pluvial sans isolant | B16: 1.2 | C16: m | D16: C2 note 3.14
... A22: Escompte Lécuyer – puisards (variante) | B22: 0 | C22: - | D22: 0 % par défaut ; mettre 30 % si l'escompte s'applique aussi aux puisards
A23: Facteur d'ajustement pavage (total ingénieur / mesure) | B23: =11019.8/(8122.3+2400.2) -> 1.0472606 | C23: - | D23: Tableau rétention C2 (pavage 11 019,8 m²) ÷ surfaces mesurées PDF
